<?xml version="1.0" ?>
<!-- =================================================================================== -->
<!-- |    This document was autogenerated by xacro from qbot_description.xacro         | -->
<!-- |    EDITING THIS FILE BY HAND IS NOT RECOMMENDED                                 | -->
<!-- =================================================================================== -->
<robot name="qbot">
  <!-- Materials -->
  <material name="blue">
    <color rgba="0 0 1 1"/>
  </material>
  <material name="red">
    <color rgba="1 0 0 1"/>
  </material>
  <material name="green">
    <color rgba="0 1 0 1"/>
  </material>
  <material name="gray">
    <color rgba="0.5 0.5 0.5 1"/>
  </material>
  <material name="black">
    <color rgba="0.1 0.1 0.1 1"/>
  </material>
  <!-- general inertia tags -->
  <!-- Model Properties -->
  <!-- Sensors -->
  <!-- gazebo references -->
  <gazebo reference="caster_wheel">
    <mu1 value="0.1"/>
    <mu2 value="1"/>
  </gazebo>
  <gazebo reference="left_wheel">
    <mu1 value="0.1"/>
    <mu2 value="0.1"/>
  </gazebo>
  <gazebo reference="right_wheel">
    <mu1 value="0.1"/>
    <mu2 value="0.1"/>
  </gazebo>
  <gazebo reference="imu">
    <always_on>true</always_on>
    <update_rate>100.0</update_rate>
    <gz_frame_id>imu</gz_frame_id>
    <topic>imu</topic>
    <imu>
      <angular_velocity>
        <x>
          <noise type="gaussian">
            <mean>0.0</mean>
            <stddev>2e-4</stddev>
          </noise>
        </x>
        <y>
          <noise type="gaussian">
            <mean>0.0</mean>
            <stddev>2e-4</stddev>
          </noise>
        </y>
        <z>
          <noise type="gaussian">
            <mean>0.0</mean>
            <stddev>2e-4</stddev>
          </noise>
        </z>
      </angular_velocity>
      <linear_acceleration>
        <x>
          <noise type="gaussian">
            <mean>0.0</mean>
            <stddev>1.7e-2</stddev>
          </noise>
        </x>
        <y>
          <noise type="gaussian">
            <mean>0.0</mean>
            <stddev>1.7e-2</stddev>
          </noise>
        </y>
        <z>
          <noise type="gaussian">
            <mean>0.0</mean>
            <stddev>1.7e-2</stddev>
          </noise>
        </z>
      </linear_acceleration>
    </imu>
  </gazebo>
  <!-- Gazebo Plugins -->
  <gazebo>
    <plugin filename="gz-sim-diff-drive-system" name="gz::sim::systems::DiffDrive">
      <left_joint>left_wheel_joint</left_joint>
      <right_joint>right_wheel_joint</right_joint>
      <frame_id>odom</frame_id>
      <child_frame_id>base_footprint</child_frame_id>
      <wheel_separation>0.1934</wheel_separation>
      <wheel_radius>0.034</wheel_radius>
      <max_linear_velocity>0.3</max_linear_velocity>
      <min_linear_velocity>-0.3</min_linear_velocity>
      <max_angular_velocity>1</max_angular_velocity>
      <min_angular_velocity>-1</min_angular_velocity>
    </plugin>
    <plugin filename="gz-sim-joint-state-publisher-system" name="gz::sim::systems::JointStatePublisher">
        </plugin>
    <plugin filename="gz-sim-imu-system" name="gz::sim::systems::Imu">
        </plugin>
  </gazebo>
  <link name="base_footprint"/>
  <link name="base_link">
    <!-- From CAD -->
    <inertial>
      <!-- <origin xyz="1.7719586332633954E-6 1.751448244030529E-4 0.0466875772049434" rpy="0.0 -0.0 0.0"/> -->
      <mass value="1.3579939912816132"/>
      <inertia ixx="0.003930134422968899" ixy="4.165452750789473E-6" ixz="6.2059583704332395E-6" iyy="0.004627442836321762" iyz="-2.140255948376241E-5" izz="0.0065795625959500755"/>
    </inertial>
    <visual>
      <origin rpy="0 0 0" xyz="0 0 -0.074"/>
      <geometry>
        <mesh filename="package://qbot_description/meshes/qbot_base.stl" scale="1 1 1"/>
      </geometry>
      <material name="gray"/>
    </visual>
    <collision>
      <origin rpy="0 0 0" xyz="0 0 0"/>
      <geometry>
        <box size="0.204 0.154 0.092"/>
      </geometry>
    </collision>
  </link>
  <link name="left_wheel">
    <!-- <visual>
                <origin rpy="0 0 0" xyz="0 0 0"/>
                <geometry>
                    <cylinder radius="${wheel_radius}" length="${wheel_thickness}"/>
                </geometry>
                <material name="gray"/>
            </visual> -->
    <collision>
      <origin rpy="0 0 0" xyz="0 0 0"/>
      <geometry>
        <cylinder length="0.02" radius="0.034"/>
      </geometry>
    </collision>
    <inertial>
      <origin rpy="0 0 0" xyz="0 0 0"/>
      <mass value="0.033"/>
      <inertia ixx="1.0637000000000003e-05" ixy="0" ixz="0" iyy="1.0637000000000003e-05" iyz="0" izz="1.9074000000000004e-05"/>
    </inertial>
  </link>
  <link name="right_wheel">
    <!-- <visual>
                <origin rpy="0 0 0" xyz="0 0 0"/>
                <geometry>
                    <cylinder radius="${wheel_radius}" length="${wheel_thickness}"/>
                </geometry>
                <material name="gray"/>
            </visual> -->
    <collision>
      <origin rpy="0 0 0" xyz="0 0 0"/>
      <geometry>
        <cylinder length="0.02" radius="0.034"/>
      </geometry>
    </collision>
    <inertial>
      <origin rpy="0 0 0" xyz="0 0 0"/>
      <mass value="0.033"/>
      <inertia ixx="1.0637000000000003e-05" ixy="0" ixz="0" iyy="1.0637000000000003e-05" iyz="0" izz="1.9074000000000004e-05"/>
    </inertial>
  </link>
  <link name="front_caster">
    <visual>
      <origin rpy="0 0 0" xyz="0 0 0"/>
      <geometry>
        <sphere radius="0.0105"/>
      </geometry>
      <material name="gray"/>
    </visual>
    <collision>
      <origin rpy="0 0 0" xyz="0 0 0"/>
      <geometry>
        <sphere radius="0.0105"/>
      </geometry>
    </collision>
    <inertial>
      <origin rpy="0 0 0" xyz="0 0 0"/>
      <mass value="0.04"/>
      <inertia ixx="1.7640000000000002e-06" ixy="0" ixz="0" iyy="1.7640000000000002e-06" iyz="0" izz="1.7640000000000002e-06"/>
    </inertial>
  </link>
  <link name="rear_caster">
    <visual>
      <origin rpy="0 0 0" xyz="0 0 0"/>
      <geometry>
        <sphere radius="0.0105"/>
      </geometry>
      <material name="gray"/>
    </visual>
    <collision>
      <origin rpy="0 0 0" xyz="0 0 0"/>
      <geometry>
        <sphere radius="0.0105"/>
      </geometry>
    </collision>
    <inertial>
      <origin rpy="0 0 0" xyz="0 0 0"/>
      <mass value="0.04"/>
      <inertia ixx="1.7640000000000002e-06" ixy="0" ixz="0" iyy="1.7640000000000002e-06" iyz="0" izz="1.7640000000000002e-06"/>
    </inertial>
  </link>
  <!-- Sensor Links -->
  <link name="lidar">
    <visual>
      <origin rpy="0 0 0" xyz="0 0 0"/>
      <geometry>
        <cylinder length="0.02" radius="0.03"/>
      </geometry>
      <material name="black"/>
    </visual>
    <visual>
      <origin rpy="0 0 0" xyz="0 0 0"/>
      <geometry>
        <box size="0.06 0.02"/>
      </geometry>
      <material name="black"/>
    </visual>
    <collision>
      <origin rpy="0 0 0" xyz="0 0 0"/>
      <geometry>
        <cylinder length="0.02" radius="0.03"/>
      </geometry>
    </collision>
    <inertial>
      <origin rpy="0 0 0" xyz="0 0 0"/>
      <mass value="0.05"/>
      <inertia ixx="1.2916666666666666e-05" ixy="0" ixz="0" iyy="1.2916666666666666e-05" iyz="0" izz="2.25e-05"/>
    </inertial>
  </link>
  <link name="imu">
    <visual>
      <origin rpy="0 0 0" xyz="0 0 0"/>
      <geometry>
        <box size="0.01 0.01 0.01"/>
      </geometry>
      <material name="green"/>
    </visual>
    <collision>
      <origin rpy="0 0 0" xyz="0 0 0"/>
      <geometry>
        <box size="0.01 0.01 0.01"/>
      </geometry>
    </collision>
    <inertial>
      <origin rpy="0 0 0" xyz="0 0 0"/>
      <mass value="0.05"/>
      <inertia ixx="8.333333333333333e-07" ixy="0" ixz="0" iyy="8.333333333333333e-07" iyz="0" izz="8.333333333333333e-07"/>
    </inertial>
  </link>
  <link name="camera">
    <visual>
      <origin rpy="0 0 0" xyz="0 0 0"/>
      <geometry>
        <box size="0.02 0.02 0.02"/>
      </geometry>
      <material name="black"/>
    </visual>
    <collision>
      <origin rpy="0 0 0" xyz="0 0 0"/>
      <geometry>
        <box size="0.02 0.02 0.02"/>
      </geometry>
    </collision>
    <inertial>
      <origin rpy="0 0 0" xyz="0 0 0"/>
      <mass value="0.05"/>
      <inertia ixx="3.3333333333333333e-06" ixy="0" ixz="0" iyy="3.3333333333333333e-06" iyz="0" izz="3.3333333333333333e-06"/>
    </inertial>
  </link>
  <!-- Joints -->
  <joint name="footprint_to_body" type="fixed">
    <parent link="base_footprint"/>
    <child link="base_link"/>
    <origin rpy="0 0 0" xyz="0 0 0.074"/>
  </joint>
  <joint name="left_wheel_joint" type="continuous">
    <origin rpy="1.5707963267948966 0 0" xyz="0 -0.0967 -0.039"/>
    <parent link="base_link"/>
    <child link="left_wheel"/>
    <axis xyz="0 0 -1"/>
  </joint>
  <joint name="right_wheel_joint" type="continuous">
    <origin rpy="1.5707963267948966 0 0" xyz="0 0.0967 -0.039"/>
    <parent link="base_link"/>
    <child link="right_wheel"/>
    <axis xyz="0 0 -1"/>
  </joint>
  <joint name="front_caster_joint" type="fixed">
    <origin rpy="0 0 0" xyz="0.07967 0 -0.062"/>
    <parent link="base_link"/>
    <child link="front_caster"/>
  </joint>
  <joint name="rear_caster_joint" type="fixed">
    <origin rpy="0 0 0" xyz="-0.07967 0 -0.062"/>
    <parent link="base_link"/>
    <child link="rear_caster"/>
  </joint>
  <!-- Sensor Joints -->
  <joint name="lidar_joint" type="fixed">
    <origin rpy="0 0 0" xyz="0 0 0.08"/>
    <parent link="base_link"/>
    <child link="lidar"/>
  </joint>
  <joint name="imu_joint" type="fixed">
    <origin rpy="0 0 0" xyz="0.05 0 0.03"/>
    <parent link="base_link"/>
    <child link="imu"/>
  </joint>
  <joint name="camera_joint" type="fixed">
    <origin rpy="0 0 0" xyz="0.08 0 0.05"/>
    <parent link="base_link"/>
    <child link="camera"/>
  </joint>
</robot>
