#VRML_SIM R2025a utf8

EXTERNPROTO "https://raw.githubusercontent.com/cyberbotics/webots/R2025a/projects/objects/backgrounds/protos/TexturedBackground.proto"
EXTERNPROTO "https://raw.githubusercontent.com/cyberbotics/webots/R2025a/projects/objects/backgrounds/protos/TexturedBackgroundLight.proto"
EXTERNPROTO "https://raw.githubusercontent.com/cyberbotics/webots/R2025a/projects/objects/floors/protos/RectangleArena.proto"
EXTERNPROTO "https://raw.githubusercontent.com/cyberbotics/webots/R2025a/projects/appearances/protos/Parquetry.proto"

WorldInfo {
}
Viewpoint {
  orientation -0.18771033731621353 0.3845146041055094 0.9038325887542542 0.9904618046730316
  position -0.5358102228396052 -0.6671207198582388 0.49319539532902235
  follow "Qbot:base_link"
}
TexturedBackground {
}
TexturedBackgroundLight {
}
RectangleArena {
  floorSize 9.26 9.26
  floorAppearance Parquetry {
  }
}
Robot {
  translation 0 0 -1107.12
  children [
    Solid {
      translation -0.0296476 -0.020027 1107.2
      rotation 0.0005222971956789632 -0.9999998318748465 0.0002519045812713635 0.023841576428015005
      children [
        Pose {
          translation 0 0 -0.074
          rotation 0 0 1 1.570796
          children [
            DEF qbot_visual CadShape {
              url [
                "/home/username/jazzy_ws/workspaces/Qbot_ws/src/qbot_description/meshes/qbot.obj"
              ]
            }
          ]
        }
        HingeJoint {
          jointParameters HingeJointParameters {
            position 148.5018902447203
            axis 0 1 0
            anchor 0 -0.0967 -0.039
          }
          device [
            RotationalMotor {
              name "left_wheel_joint"
              maxTorque 10000
            }
            PositionSensor {
              name "left_wheel_joint_sensor"
            }
          ]
          endPoint Solid {
            translation 0 -0.0967 -0.039
            rotation 0.30370611588408364 -0.6737072405083652 0.6737070203443092 2.5518856257568734
            name "left_wheel"
            boundingObject Cylinder {
              height 0.02
              radius 0.034
            }
            physics Physics {
              density -1
              mass 0.033
              centerOfMass [
                0 0 0
              ]
              inertiaMatrix [
                1.0637e-05 1.0637e-05 1.9074e-05
                0 0 0
              ]
            }
          }
        }
        HingeJoint {
          jointParameters HingeJointParameters {
            position 148.50189024448954
            axis 0 1 0
            anchor 0 0.0967 -0.039
          }
          device [
            RotationalMotor {
              name "right_wheel_joint"
              maxTorque 10000
            }
            PositionSensor {
              name "right_wheel_joint_sensor"
            }
          ]
          endPoint Solid {
            translation 0 0.0967 -0.039
            rotation 0.30370611579918305 -0.6737072405275011 0.6737070203634464 2.551885625912334
            name "right_wheel"
            boundingObject Cylinder {
              height 0.02
              radius 0.034
            }
            physics Physics {
              density -1
              mass 0.033
              centerOfMass [
                0 0 0
              ]
              inertiaMatrix [
                1.0637e-05 1.0637e-05 1.9074e-05
                0 0 0
              ]
            }
          }
        }
        Solid {
          translation 0.07967 0 -0.062
          children [
            Shape {
              appearance DEF gray PBRAppearance {
                baseColor 0.5 0.5 0.5
                roughness 1
                metalness 0
              }
              geometry Sphere {
                radius 0.0105
              }
            }
          ]
          name "front_caster"
          boundingObject Sphere {
            radius 0.0105
          }
          physics Physics {
            density -1
            mass 0.04
            centerOfMass [
              0 0 0
            ]
            inertiaMatrix [
              1.764e-06 1.764e-06 1.764e-06
              0 0 0
            ]
          }
        }
        Solid {
          translation -0.07967 0 -0.062
          children [
            Shape {
              appearance USE gray
              geometry Sphere {
                radius 0.0105
              }
            }
          ]
          name "rear_caster"
          boundingObject Sphere {
            radius 0.0105
          }
          physics Physics {
            density -1
            mass 0.04
            centerOfMass [
              0 0 0
            ]
            inertiaMatrix [
              1.764e-06 1.764e-06 1.764e-06
              0 0 0
            ]
          }
        }
        Solid {
          translation 0 0 0.075
          children [
            Shape {
              appearance DEF black PBRAppearance {
                baseColor 0.5 0.5 0.5
                roughness 1
                metalness 0
              }
              geometry Cylinder {
                height 0.02
                radius 0.03
              }
            }
            Pose {
              translation 0 0 -0.02
              children [
                Shape {
                  appearance USE black
                  geometry Box {
                    size 0.066 0.066 0.02
                  }
                }
              ]
            }
          ]
          name "lidar"
          boundingObject Cylinder {
            height 0.02
            radius 0.03
          }
          physics Physics {
            density -1
            mass 0.05
            centerOfMass [
              0 0 0
            ]
            inertiaMatrix [
              1.291667e-05 1.291667e-05 2.25e-05
              0 0 0
            ]
          }
        }
        Solid {
          translation 0.05 0 0.03
          children [
            Shape {
              appearance DEF green PBRAppearance {
                baseColor 0.5 0.5 0.5
                roughness 1
                metalness 0
              }
              geometry Box {
                size 0.01 0.01 0.01
              }
            }
          ]
          name "imu"
          boundingObject Box {
            size 0.01 0.01 0.01
          }
          physics Physics {
            density -1
            mass 0.05
            centerOfMass [
              0 0 0
            ]
            inertiaMatrix [
              8.333333e-07 8.333333e-07 8.333333e-07
              0 0 0
            ]
          }
        }
        Solid {
          translation 0.09 0 0.055
          children [
            Shape {
              appearance USE black
              geometry Box {
                size 0.02 0.02 0.02
              }
            }
          ]
          name "camera"
          boundingObject Box {
            size 0.02 0.02 0.02
          }
          physics Physics {
            density -1
            mass 0.05
            centerOfMass [
              0 0 0
            ]
            inertiaMatrix [
              3.333333e-06 3.333333e-06 3.333333e-06
              0 0 0
            ]
          }
        }
      ]
      name "base_link"
      boundingObject Box {
        size 0.204 0.154 0.092
      }
      physics Physics {
        density -1
        mass 1.357994
        centerOfMass [
          0 0 0
        ]
        inertiaMatrix [
          0.003930134 0.004627443 0.006579563
          4.165453e-06 6.205958e-06 -2.140256e-05
        ]
      }
    }
  ]
  name "Qbot"
  physics Physics {
  }
  controller "diff_drive_controller"
}
