<?xml version="1.0" ?>
<!-- =================================================================================== -->
<!-- |    This document was autogenerated by xacro from qbot_description.xacro         | -->
<!-- |    EDITING THIS FILE BY HAND IS NOT RECOMMENDED                                 | -->
<!-- =================================================================================== -->
<robot name="qbot">
  <!-- Materials -->
  <material name="blue">
    <color rgba="0 0 1 1"/>
  </material>
  <material name="red">
    <color rgba="1 0 0 1"/>
  </material>
  <material name="green">
    <color rgba="0 1 0 1"/>
  </material>
  <material name="gray">
    <color rgba="0.5 0.5 0.5 1"/>
  </material>
  <material name="black">
    <color rgba="0.1 0.1 0.1 1"/>
  </material>
  <!-- general inertia tags -->
  <!-- Model Properties -->
  <link name="base_footprint"/>
  <link name="base_link">
    <!-- From CAD -->
    <inertial>
      <!-- <origin xyz="1.7719586332633954E-6 1.751448244030529E-4 0.0466875772049434" rpy="0.0 -0.0 0.0"/> -->
      <mass value="1.3579939912816132"/>
      <inertia ixx="0.003930134422968899" ixy="4.165452750789473E-6" ixz="6.2059583704332395E-6" iyy="0.004627442836321762" iyz="-2.140255948376241E-5" izz="0.0065795625959500755"/>
    </inertial>
    <visual>
      <origin rpy="0 0 0" xyz="0 0 -0.074"/>
      <geometry>
        <mesh filename="package://qbot_description/meshes/qbot_base.stl" scale="1 1 1"/>
      </geometry>
      <material name="gray"/>
    </visual>
    <collision>
      <origin rpy="0 0 0" xyz="0 0 -0.074"/>
      <geometry>
        <box size="0.154 0.204 0.092"/>
      </geometry>
    </collision>
  </link>
  <link name="left_wheel">
    <visual>
      <origin rpy="0 0 0" xyz="0 0 0"/>
      <geometry>
        <cylinder length="0.02" radius="0.034"/>
      </geometry>
      <material name="black"/>
    </visual>
    <collision>
      <origin rpy="0 0 0" xyz="0 0 0"/>
      <geometry>
        <cylinder length="0.02" radius="0.034"/>
      </geometry>
    </collision>
    <inertial>
      <origin rpy="0 0 0" xyz="0 0 0"/>
      <mass value="0.033"/>
      <inertia ixx="1.0637000000000003e-05" ixy="0" ixz="0" iyy="1.0637000000000003e-05" iyz="0" izz="1.9074000000000004e-05"/>
    </inertial>
  </link>
  <link name="right_wheel">
    <visual>
      <origin rpy="0 0 0" xyz="0 0 0"/>
      <geometry>
        <cylinder length="0.02" radius="0.034"/>
      </geometry>
      <material name="black"/>
    </visual>
    <collision>
      <origin rpy="0 0 0" xyz="0 0 0"/>
      <geometry>
        <cylinder length="0.02" radius="0.034"/>
      </geometry>
    </collision>
    <inertial>
      <origin rpy="0 0 0" xyz="0 0 0"/>
      <mass value="0.033"/>
      <inertia ixx="1.0637000000000003e-05" ixy="0" ixz="0" iyy="1.0637000000000003e-05" iyz="0" izz="1.9074000000000004e-05"/>
    </inertial>
  </link>
  <link name="front_caster">
    <visual>
      <origin rpy="0 0 0" xyz="0 0 0"/>
      <geometry>
        <sphere radius="0.0105"/>
      </geometry>
      <material name="red"/>
    </visual>
    <collision>
      <origin rpy="0 0 0" xyz="0 0 0"/>
      <geometry>
        <sphere radius="0.0105"/>
      </geometry>
    </collision>
    <inertial>
      <origin rpy="0 0 0" xyz="0 0 0"/>
      <mass value="0.04"/>
      <inertia ixx="1.7640000000000002e-06" ixy="0" ixz="0" iyy="1.7640000000000002e-06" iyz="0" izz="1.7640000000000002e-06"/>
    </inertial>
  </link>
  <link name="rear_caster">
    <visual>
      <origin rpy="0 0 0" xyz="0 0 0"/>
      <geometry>
        <sphere radius="0.0105"/>
      </geometry>
      <material name="red"/>
    </visual>
    <collision>
      <origin rpy="0 0 0" xyz="0 0 0"/>
      <geometry>
        <sphere radius="0.0105"/>
      </geometry>
    </collision>
    <inertial>
      <origin rpy="0 0 0" xyz="0 0 0"/>
      <mass value="0.04"/>
      <inertia ixx="1.7640000000000002e-06" ixy="0" ixz="0" iyy="1.7640000000000002e-06" iyz="0" izz="1.7640000000000002e-06"/>
    </inertial>
  </link>
  <joint name="footprint_to_body" type="fixed">
    <parent link="base_footprint"/>
    <child link="base_link"/>
    <origin rpy="0 0 0" xyz="0 0 0.074"/>
  </joint>
  <joint name="left_wheel_joint" type="continuous">
    <origin rpy="0 1.5707963267948966 0" xyz="0.1067 0 0.034"/>
    <parent link="base_link"/>
    <child link="left_wheel"/>
    <axis xyz="0 0 1"/>
  </joint>
  <joint name="right_wheel_joint" type="continuous">
    <origin rpy="0 -1.5707963267948966 0" xyz="-0.1067 0 0.034"/>
    <parent link="base_link"/>
    <child link="right_wheel"/>
    <axis xyz="0 0 1"/>
  </joint>
  <joint name="front_caster_joint" type="fixed">
    <origin rpy="0 0 0" xyz="0 0.07967 -0.062"/>
    <parent link="base_link"/>
    <child link="front_caster"/>
  </joint>
  <joint name="rear_caster_joint" type="fixed">
    <origin rpy="0 0 0" xyz="0 -0.07967 -0.062"/>
    <parent link="base_link"/>
    <child link="rear_caster"/>
  </joint>
</robot>
